<?xml version='1.0'?>
<sdf version="1.4">
<model name="dropping box">
  <pose>0 0 0.08 0 0 0</pose>
  <static>true</static>
    <link name="base_face">
        <inertial>
         <mass>0.5</mass>
         <inertia>
            <ixx>0.083</ixx>
            <ixy>0.0</ixy>
            <ixz>0.0</ixz>
            <iyy>0.083</iyy>
            <iyz>0.0</iyz>
            <izz>0.083</izz>
         </inertia>
        </inertial>
        <collision name="collision">
            <geometry>
                <box>
                    <size>0.5 1 0.05</size>
                </box>
            </geometry>
        </collision>
        <visual name="visual">
            <geometry>
                <box>
                    <size>0.5 1 0.05</size>
                </box>
            </geometry>
            <material>
                <script>
                    <uri>file://media/materials/scripts/gazebo.material</uri>
                    <name>Gazebo/Gold</name>
                </script>
            </material>
        </visual>
    </link>

    <link name="front_face">
      <pose>0.225 0 0.375 0 0 0</pose>
      <inertial>
        <mass>0.5</mass>
        <inertia>
          <ixx>0.083</ixx>
          <ixy>0.0</ixy>
          <ixz>0.0</ixz>
          <iyy>0.083</iyy>
          <iyz>0.0</iyz>
          <izz>0.083</izz>
        </inertia>
      </inertial>
      <collision name="collision">
        <geometry>
        <box>
          <size>0.05 1 0.8</size>
        </box>
        </geometry>
      </collision>
      <visual name="visual">
        <geometry>
        <box>
          <size>0.05 1 0.8</size>
        </box>
        </geometry>
        <material>
            <script>
              <uri>file://media/materials/scripts/gazebo.material</uri>
              <name>Gazebo/Gold</name>
            </script>
        </material>
      </visual>
    </link>

    <link name="rear_face">
      <pose>-0.225 0 0.375 0 0 0</pose>
      <inertial>
        <mass>0.5</mass>
        <inertia>
          <ixx>0.083</ixx>
          <ixy>0.0</ixy>
          <ixz>0.0</ixz>
          <iyy>0.083</iyy>
          <iyz>0.0</iyz>
          <izz>0.083</izz>
        </inertia>
      </inertial>
      <collision name="collision">
        <geometry>
        <box>
          <size>0.05 1 0.8</size>
        </box>
        </geometry>
      </collision>
      <visual name="visual">
        <geometry>
        <box>
          <size>0.05 1 0.8</size>
        </box>
        </geometry>
        <material>
            <script>
              <uri>file://media/materials/scripts/gazebo.material</uri>
              <name>Gazebo/Gold</name>
            </script>
        </material>
      </visual>
    </link>

    <link name="right_face">
      <pose>0 0.475 0.375 0 0 0</pose>
      <inertial>
        <mass>0.5</mass>
        <inertia>
          <ixx>0.083</ixx>
          <ixy>0.0</ixy>
          <ixz>0.0</ixz>
          <iyy>0.083</iyy>
          <iyz>0.0</iyz>
          <izz>0.083</izz>
        </inertia>
      </inertial>
      <collision name="collision">
        <geometry>
        <box>
          <size>0.5 0.05 0.8</size>
        </box>
        </geometry>
      </collision>
      <visual name="visual">
        <geometry>
        <box>
          <size>0.5 0.05 0.8</size>
        </box>
        </geometry>
        <material>
            <script>
              <uri>file://media/materials/scripts/gazebo.material</uri>
              <name>Gazebo/Gold</name>
            </script>
        </material>
      </visual>
    </link>

    <link name="left_face">
      <pose>0 -0.475 0.375 0 0 0</pose>
      <inertial>
        <mass>0.5</mass>
        <inertia>
          <ixx>0.083</ixx>
          <ixy>0.0</ixy>
          <ixz>0.0</ixz>
          <iyy>0.083</iyy>
          <iyz>0.0</iyz>
          <izz>0.083</izz>
        </inertia>
      </inertial>
      <collision name="collision">
        <geometry>
        <box>
          <size>0.5 0.05 0.8</size>
        </box>
        </geometry>
      </collision>
      <visual name="visual">
        <geometry>
        <box>
          <size>0.5 0.05 0.8</size>
        </box>
        </geometry>
        <material>
            <script>
              <uri>file://media/materials/scripts/gazebo.material</uri>
              <name>Gazebo/Gold</name>
            </script>
        </material>
      </visual>
    </link>

    <joint name="base_front" type="revolute">
        <child>front_face</child>
        <parent>base_face</parent>
        <pose>1 1 1 0 0 0</pose>
        <axis>
          <xyz>1 1 1</xyz>
        </axis>
    </joint>

    <joint name="base_rear" type="revolute">
        <child>rear_face</child>
        <parent>base_face</parent>
        <pose>1 1 1 0 0 0</pose>
        <axis>
          <xyz>1 1 1</xyz>
        </axis>
    </joint>

    <joint name="base_right" type="revolute">
        <child>right_face</child>
        <parent>base_face</parent>
        <pose>1 1 1 0 0 0</pose>
        <axis>
          <xyz>1 1 1</xyz>
        </axis>
    </joint>

    <joint name="base_left" type="revolute">
        <child>left_face</child>
        <parent>base_face</parent>
        <pose>1 1 1 0 0 0</pose>
        <axis>
          <xyz>1 1 1</xyz>
        </axis>
    </joint>

  </model>
</sdf>
